Workbook
Name actuals: OFFSET('[1]Actuals Update'!$A$1,0,0,COUNTA('[1]Actuals Update'!$A$1:$A$65536),13)
Name altdesc: '[1]Tables and Customizations'!$A$25:$B$140
Name ASSN: [1]Assumptions!$C$4
Name Beg_Bal: #REF!
Name curbudget: OFFSET('[1]Current Budget Update'!$A$1,0,0,COUNTA('[1]Current Budget Update'!$A$1:$A$65536),13)
Name End_Bal: '[2]Loan Amortization Schedule'!$I$18:$I$377
Name Extra_Pay: #REF!
Name Extra_Pay: #REF!
Name Extra_Pay: #REF!
Name Extra_Pay: #REF!
Name glai: '[1]PM Budget Input'!$F$7:$AA$971
Name Header_Row: ROW('[2]Loan Amortization Schedule'!$A$17:$IV$17)
Name INSPREAD: OFFSET('[1]PM Budget Input'!$A$1,0,0,COUNTA('[1]PM Budget Input'!$A$1:$A$65536),19)
Name Int: #REF!
Name intable: OFFSET('[1]PM Budget Input'!$F$8,0,0,COUNTA('[1]PM Budget Input'!$F$1:$F$65536),7)
Name Interest_Rate: '[2]Loan Amortization Schedule'!$D$6
Name Last_Row: IF(Values_Entered,Header_Row+Number_of_Payments,Header_Row)
Name listg: OFFSET('[1]PM Budget Input'!$F$8,0,0,COUNTA('[1]PM Budget Input'!$A$1:$A$65536),2)
Name Loan_Amount: '[2]Loan Amortization Schedule'!$D$5
Name Loan_Start: '[2]Loan Amortization Schedule'!$D$9
Name Loan_Years: '[2]Loan Amortization Schedule'!$D$7
Name Monkey: '[2]Lead Sheet'!$B$7:$I$67
Name Num_Pmt_Per_Year: #REF!
Name Num_Pmt_Per_Year: #REF!
Name Num_Pmt_Per_Year: #REF!
Name Num_Pmt_Per_Year: #REF!
Name Number_of_Payments: MATCH(0.01,End_Bal,-1)+1
Name outtable: OFFSET('[1]PM Budget Input'!$F$103,0,0,COUNTA('[1]PM Budget Input'!$F$1:$F$65536),10)
Name Pay_Num: #REF!
Name prevbudget: OFFSET('[1]Previous Budget Update'!$A$1,0,0,COUNTA('[1]Previous Budget Update'!$A$1:$A$65536),13)
Name Princ: #REF!
Name projection: OFFSET('[1]Projection Update'!$A$1,0,0,COUNTA('[1]Projection Update'!$A$1:$A$65536),13)
Name Sched_Pay: #REF!
Name Scheduled_Extra_Payments: #REF!
Name Scheduled_Monthly_Payment: #REF!
Name Total_Pay: #REF!
Name Total_Pay: #REF!
Name Total_Pay: #REF!
Name Total_Pay: #REF!
Name Units: #REF!
Name Values_Entered: IF(Loan_Amount*Interest_Rate*Loan_Years*Loan_Start>0,1,0)
Name YEAR: '[1]Tables and Customizations'!$B$17

Sheet Calc
F4: Assessments for Option 1
B6: =DATE(C9+1,B9,26) -> 26
B9: =MONTH(Assumptions!B23)-MONTH(Assumptions!D8) -> -11 | C9: =YEAR(Assumptions!B23) -> 1900 | D9: =MONTH(Assumptions!B23) -> 1 | E9: =DAY(Assumptions!B23) -> 0 | G9: =IF(YEAR(Assumptions!$D$8)=12,MONTH(Assumptions!$D$16)+1-MONTH(Assumptions!$D$8),IF(MONTH(Assumptions!$D$8)<MONTH(Assumptions!$D$16),12-(MONTH(Assumptions!D16)-MONTH(Assumptions!D8)),MONTH(Assumptions!$D$8)-MONTH(Assumptions!$D$16))) -> 5 | H9: =IF(YEAR(Assumptions!$D$8)=12,MONTH(Assumptions!$D$16)+1-MONTH(Assumptions!$D$8),IF(MONTH(Assumptions!$D$8)<MONTH(Assumptions!$D$16),12-(MONTH(Assumptions!$D$16)-MONTH(Assumptions!$D$8)),MONTH(Assumptions!$D$8)-MONTH(Assumptions!$D$16))) -> 5
B13: =Assumptions!B24*12 -> 0
A15: Loan Clac | B15: =IF((MONTH(B18)-MONTH(Assumptions!B32))+1=12,0,(MONTH(B18)-MONTH(Assumptions!B32))+1) -> 0 | C15: =IF((MONTH(C18)-MONTH(Assumptions!B32))+1=12,0,(MONTH(C18)-MONTH(Assumptions!B32))+1) -> 0 | D15: =IF((MONTH(D18)-MONTH(Assumptions!B32))+1=12,0,(MONTH(D18)-MONTH(Assumptions!B32))+1) -> 0 | E15: =IF((MONTH(E18)-MONTH(Assumptions!B32))+1=12,0,(MONTH(E18)-MONTH(Assumptions!B32))+1) -> 0 | F15: =IF((MONTH(F18)-MONTH(Assumptions!B32))+1=12,0,(MONTH(F18)-MONTH(Assumptions!B32))+1) -> 0 | G15: =IF((MONTH(G18)-MONTH(Assumptions!B32))+1=12,0,(MONTH(G18)-MONTH(Assumptions!B32))+1) -> 0 | H15: =IF((MONTH(H18)-MONTH(Assumptions!B32))+1=12,0,(MONTH(H18)-MONTH(Assumptions!B32))+1) -> 0 | I15: =IF((MONTH(I18)-MONTH(Assumptions!B32))+1=12,0,(MONTH(I18)-MONTH(Assumptions!B32))+1) -> 0 | J15: =IF((MONTH(J18)-MONTH(Assumptions!B32))+1=12,0,(MONTH(J18)-MONTH(Assumptions!B32))+1) -> 0 | K15: =IF((MONTH(K18)-MONTH(Assumptions!B32))+1=12,0,(MONTH(K18)-MONTH(Assumptions!B32))+1) -> 0 | L15: =IF((MONTH(L18)-MONTH(Assumptions!B32))+1=12,0,(MONTH(L18)-MONTH(Assumptions!B32))+1) -> 0 | M15: =IF((MONTH(M18)-MONTH(Assumptions!B32))+1=12,0,(MONTH(M18)-MONTH(Assumptions!B32))+1) -> 0 | N15: =IF((MONTH(N18)-MONTH(Assumptions!B32))+1=12,0,(MONTH(N18)-MONTH(Assumptions!B32))+1) -> 0 | O15: =IF((MONTH(O18)-MONTH(Assumptions!B32))+1=12,0,(MONTH(O18)-MONTH(Assumptions!B32))+1) -> 0 | P15: =IF((MONTH(P18)-MONTH(Assumptions!B32))+1=12,0,(MONTH(P18)-MONTH(Assumptions!B32))+1) -> 0
A16: SA Calc | B16: =IF((MONTH(B18)-MONTH(Assumptions!B22))+1=12,0,(MONTH(B18)-MONTH(Assumptions!B22))+1) -> 0 | C16: =IF((MONTH(C18)-MONTH(Assumptions!B22))+1=12,0,(MONTH(C18)-MONTH(Assumptions!B22))+1) -> 0 | D16: =IF((MONTH(D18)-MONTH(Assumptions!B22))+1=12,0,(MONTH(D18)-MONTH(Assumptions!B22))+1) -> 0 | E16: =IF((MONTH(E18)-MONTH(Assumptions!B22))+1=12,0,(MONTH(E18)-MONTH(Assumptions!B22))+1) -> 0 | F16: =IF((MONTH(F18)-MONTH(Assumptions!B22))+1=12,0,(MONTH(F18)-MONTH(Assumptions!B22))+1) -> 0 | G16: =IF((MONTH(G18)-MONTH(Assumptions!B22))+1=12,0,(MONTH(G18)-MONTH(Assumptions!B22))+1) -> 0 | H16: =IF((MONTH(H18)-MONTH(Assumptions!B22))+1=12,0,(MONTH(H18)-MONTH(Assumptions!B22))+1) -> 0 | I16: =IF((MONTH(I18)-MONTH(Assumptions!B22))+1=12,0,(MONTH(I18)-MONTH(Assumptions!B22))+1) -> 0 | J16: =IF((MONTH(J18)-MONTH(Assumptions!B22))+1=12,0,(MONTH(J18)-MONTH(Assumptions!B22))+1) -> 0 | K16: =IF((MONTH(K18)-MONTH(Assumptions!B22))+1=12,0,(MONTH(K18)-MONTH(Assumptions!B22))+1) -> 0 | L16: =IF((MONTH(L18)-MONTH(Assumptions!B22))+1=12,0,(MONTH(L18)-MONTH(Assumptions!B22))+1) -> 0 | M16: =IF((MONTH(M18)-MONTH(Assumptions!B22))+1=12,0,(MONTH(M18)-MONTH(Assumptions!B22))+1) -> 0 | N16: =IF((MONTH(N18)-MONTH(Assumptions!B22))+1=12,0,(MONTH(N18)-MONTH(Assumptions!B22))+1) -> 0 | O16: =IF((MONTH(O18)-MONTH(Assumptions!B22))+1=12,0,(MONTH(O18)-MONTH(Assumptions!B22))+1) -> 0 | P16: =IF((MONTH(P18)-MONTH(Assumptions!B22))+1=12,0,(MONTH(P18)-MONTH(Assumptions!B22))+1) -> 0
A17: Beg | B17: =DATE(B19,IF(MONTH(Assumptions!D8)=12,1,MONTH(Assumptions!D8)+1),1) -> 41275 | C17: =DATE(C19,IF(MONTH(Assumptions!D8)=12,1,MONTH(Assumptions!D8)+1),1) -> 41640 | D17: =DATE(D19,IF(MONTH(Assumptions!D8)=12,1,MONTH(Assumptions!D8)+1),1) -> 42005 | E17: =DATE(E19,IF(MONTH(Assumptions!D8)=12,1,MONTH(Assumptions!D8)+1),1) -> 42370 | F17: =DATE(F19,IF(MONTH(Assumptions!D8)=12,1,MONTH(Assumptions!D8)+1),1) -> 42736 | G17: =DATE(G19,IF(MONTH(Assumptions!D8)=12,1,MONTH(Assumptions!D8)+1),1) -> 43101 | H17: =DATE(H19,IF(MONTH(Assumptions!D8)=12,1,MONTH(Assumptions!D8)+1),1) -> 43466 | I17: =DATE(I19,IF(MONTH(Assumptions!D8)=12,1,MONTH(Assumptions!D8)+1),1) -> 43831 | J17: =DATE(J19,IF(MONTH(Assumptions!D8)=12,1,MONTH(Assumptions!D8)+1),1) -> 44197 | K17: =DATE(K19,IF(MONTH(Assumptions!D8)=12,1,MONTH(Assumptions!D8)+1),1) -> 44562 | L17: =DATE(L19,IF(MONTH(Assumptions!D8)=12,1,MONTH(Assumptions!D8)+1),1) -> 44927 | M17: =DATE(M19,IF(MONTH(Assumptions!D8)=12,1,MONTH(Assumptions!D8)+1),1) -> 45292 | N17: =DATE(N19,IF(MONTH(Assumptions!D8)=12,1,MONTH(Assumptions!D8)+1),1) -> 45658 | O17: =DATE(O19,IF(MONTH(Assumptions!D8)=12,1,MONTH(Assumptions!D8)+1),1) -> 46023 | P17: =DATE(P19,IF(MONTH(Assumptions!D8)=12,1,MONTH(Assumptions!D8)+1),1) -> 46388
A18: End | B18: =DATE(IF(MONTH(Assumptions!D8)=12,B19,B19+1),MONTH(Assumptions!D8),DAY(Assumptions!D8)) -> 41639 | C18: =DATE(IF(MONTH(Assumptions!D8)=12,C19,C19+1),MONTH(Assumptions!D8),DAY(Assumptions!D8)) -> 42004 | D18: =DATE(IF(MONTH(Assumptions!D8)=12,D19,D19+1),MONTH(Assumptions!D8),DAY(Assumptions!D8)) -> 42369 | E18: =DATE(IF(MONTH(Assumptions!D8)=12,E19,E19+1),MONTH(Assumptions!D8),DAY(Assumptions!D8)) -> 42735 | F18: =DATE(IF(MONTH(Assumptions!D8)=12,F19,F19+1),MONTH(Assumptions!D8),DAY(Assumptions!D8)) -> 43100 | G18: =DATE(IF(MONTH(Assumptions!D8)=12,G19,G19+1),MONTH(Assumptions!D8),DAY(Assumptions!D8)) -> 43465 | H18: =DATE(IF(MONTH(Assumptions!D8)=12,H19,H19+1),MONTH(Assumptions!D8),DAY(Assumptions!D8)) -> 43830 | I18: =DATE(IF(MONTH(Assumptions!D8)=12,I19,I19+1),MONTH(Assumptions!D8),DAY(Assumptions!D8)) -> 44196 | J18: =DATE(IF(MONTH(Assumptions!D8)=12,J19,J19+1),MONTH(Assumptions!D8),DAY(Assumptions!D8)) -> 44561 | K18: =DATE(IF(MONTH(Assumptions!D8)=12,K19,K19+1),MONTH(Assumptions!D8),DAY(Assumptions!D8)) -> 44926 | L18: =DATE(IF(MONTH(Assumptions!D8)=12,L19,L19+1),MONTH(Assumptions!D8),DAY(Assumptions!D8)) -> 45291 | M18: =DATE(IF(MONTH(Assumptions!D8)=12,M19,M19+1),MONTH(Assumptions!D8),DAY(Assumptions!D8)) -> 45657 | N18: =DATE(IF(MONTH(Assumptions!D8)=12,N19,N19+1),MONTH(Assumptions!D8),DAY(Assumptions!D8)) -> 46022 | O18: =DATE(IF(MONTH(Assumptions!D8)=12,O19,O19+1),MONTH(Assumptions!D8),DAY(Assumptions!D8)) -> 46387 | P18: =DATE(IF(MONTH(Assumptions!D8)=12,P19,P19+1),MONTH(Assumptions!D8),DAY(Assumptions!D8)) -> 46752
B19: =Assumptions!D7 -> 2013 | C19: =+B19+1 -> 2014 | D19: =+C19+1 -> 2015 | E19: =+D19+1 -> 2016 | F19: =+E19+1 -> 2017 | G19: =+F19+1 -> 2018 | H19: =+G19+1 -> 2019 | I19: =+H19+1 -> 2020 | J19: =+I19+1 -> 2021 | ... P19: =+O19+1 -> 2027
A20: SA Month | B20: =IF(YEAR(Assumptions!B22)=B19,IF(MONTH(Assumptions!D8)=12,12-MONTH(Assumptions!B22)+1,IF(MONTH(Assumptions!B22)<MONTH(Assumptions!D8),(MONTH(Assumptions!D8)-MONTH(Assumptions!B22))+1,IF(MONTH(Assumptions!B22)=MONTH(Assumptions!D8),1,""))),IF(AND(A20="",YEAR(Assumptions!B22)+1=B19),((MONTH(B18)+12)-MONTH(Assumptions!B22))+1,IF(YEAR($B$6)=B19,$B$13-SUM(A$20:$B20),IF(B19<YEAR(Assumptions!B22),0,IF(B19<YEAR($B$6),12,IF(B19>YEAR($B$6),0)))))) -> 0 | C20: =IF(YEAR(Assumptions!B22)=C19,IF(MONTH(Assumptions!D8)=12,12-MONTH(Assumptions!B22)+1,IF(MONTH(Assumptions!B22)<MONTH(Assumptions!D8),(MONTH(Assumptions!D8)-MONTH(Assumptions!B22))+1,IF(MONTH(Assumptions!B22)=MONTH(Assumptions!D8),1,""))),IF(AND(B20="",YEAR(Assumptions!B22)+1=C19),((MONTH(C18)+12)-MONTH(Assumptions!B22))+1,IF(YEAR($B$6)=C19,$B$13-SUM(B$20:$B20),IF(C19<YEAR(Assumptions!B22),"",IF(C19<YEAR($B$6),12,IF(C19>YEAR($B$6),"")))))) | D20: =IF(YEAR(Assumptions!B22)=D19,IF(MONTH(Assumptions!D8)=12,12-MONTH(Assumptions!B22)+1,IF(MONTH(Assumptions!B22)<MONTH(Assumptions!D8),(MONTH(Assumptions!D8)-MONTH(Assumptions!B22))+1,IF(MONTH(Assumptions!B22)=MONTH(Assumptions!D8),1,""))),IF(AND(C20="",YEAR(Assumptions!B22)+1=D19),((MONTH(D18)+12)-MONTH(Assumptions!B22))+1,IF(YEAR($B$6)=D19,$B$13-SUM($B$20:C20),IF(D19<YEAR(Assumptions!B22),"",IF(D19<YEAR($B$6),12,IF(D19>YEAR($B$6),"")))))) | E20: =IF(YEAR(Assumptions!B22)=E19,IF(MONTH(Assumptions!D8)=12,12-MONTH(Assumptions!B22)+1,IF(MONTH(Assumptions!B22)<MONTH(Assumptions!D8),(MONTH(Assumptions!D8)-MONTH(Assumptions!B22))+1,IF(MONTH(Assumptions!B22)=MONTH(Assumptions!D8),1,""))),IF(AND(D20="",YEAR(Assumptions!B22)+1=E19),((MONTH(E18)+12)-MONTH(Assumptions!B22))+1,IF(YEAR($B$6)=E19,$B$13-SUM($B$20:D20),IF(E19<YEAR(Assumptions!B22),"",IF(E19<YEAR($B$6),12,IF(E19>YEAR($B$6),"")))))) | F20: =IF(YEAR(Assumptions!B22)=F19,IF(MONTH(Assumptions!D8)=12,12-MONTH(Assumptions!B22)+1,IF(MONTH(Assumptions!B22)<MONTH(Assumptions!D8),(MONTH(Assumptions!D8)-MONTH(Assumptions!B22))+1,IF(MONTH(Assumptions!B22)=MONTH(Assumptions!D8),1,""))),IF(AND(E20="",YEAR(Assumptions!B22)+1=F19),((MONTH(F18)+12)-MONTH(Assumptions!B22))+1,IF(YEAR($B$6)=F19,$B$13-SUM($B$20:E20),IF(F19<YEAR(Assumptions!B22),"",IF(F19<YEAR($B$6),12,IF(F19>YEAR($B$6),"")))))) | G20: =IF(YEAR(Assumptions!B22)=G19,IF(MONTH(Assumptions!D8)=12,12-MONTH(Assumptions!B22)+1,IF(MONTH(Assumptions!B22)<MONTH(Assumptions!D8),(MONTH(Assumptions!D8)-MONTH(Assumptions!B22))+1,IF(MONTH(Assumptions!B22)=MONTH(Assumptions!D8),1,""))),IF(AND(F20="",YEAR(Assumptions!B22)+1=G19),((MONTH(G18)+12)-MONTH(Assumptions!B22))+1,IF(YEAR($B$6)=G19,$B$13-SUM($B$20:F20),IF(G19<YEAR(Assumptions!B22),"",IF(G19<YEAR($B$6),12,IF(G19>YEAR($B$6),"")))))) | H20: =IF(YEAR(Assumptions!B22)=H19,IF(MONTH(Assumptions!D8)=12,12-MONTH(Assumptions!B22)+1,IF(MONTH(Assumptions!B22)<MONTH(Assumptions!D8),(MONTH(Assumptions!D8)-MONTH(Assumptions!B22))+1,IF(MONTH(Assumptions!B22)=MONTH(Assumptions!D8),1,""))),IF(AND(G20="",YEAR(Assumptions!B22)+1=H19),((MONTH(H18)+12)-MONTH(Assumptions!B22))+1,IF(YEAR($B$6)=H19,$B$13-SUM($B$20:G20),IF(H19<YEAR(Assumptions!B22),"",IF(H19<YEAR($B$6),12,IF(H19>YEAR($B$6),"")))))) | I20: =IF(YEAR(Assumptions!B22)=I19,IF(MONTH(Assumptions!D8)=12,12-MONTH(Assumptions!B22)+1,IF(MONTH(Assumptions!B22)<MONTH(Assumptions!D8),(MONTH(Assumptions!D8)-MONTH(Assumptions!B22))+1,IF(MONTH(Assumptions!B22)=MONTH(Assumptions!D8),1,""))),IF(AND(H20="",YEAR(Assumptions!B22)+1=I19),((MONTH(I18)+12)-MONTH(Assumptions!B22))+1,IF(YEAR($B$6)=I19,$B$13-SUM($B$20:H20),IF(I19<YEAR(Assumptions!B22),"",IF(I19<YEAR($B$6),12,IF(I19>YEAR($B$6),"")))))) | J20: =IF(YEAR(Assumptions!B22)=J19,IF(MONTH(Assumptions!D8)=12,12-MONTH(Assumptions!B22)+1,IF(MONTH(Assumptions!B22)<MONTH(Assumptions!D8),(MONTH(Assumptions!D8)-MONTH(Assumptions!B22))+1,IF(MONTH(Assumptions!B22)=MONTH(Assumptions!D8),1,""))),IF(AND(I20="",YEAR(Assumptions!B22)+1=J19),((MONTH(J18)+12)-MONTH(Assumptions!B22))+1,IF(YEAR($B$6)=J19,$B$13-SUM($B$20:I20),IF(J19<YEAR(Assumptions!B22),"",IF(J19<YEAR($B$6),12,IF(J19>YEAR($B$6),"")))))) | K20: =IF(YEAR(Assumptions!B22)=K19,IF(MONTH(Assumptions!D8)=12,12-MONTH(Assumptions!B22)+1,IF(MONTH(Assumptions!B22)<MONTH(Assumptions!D8),(MONTH(Assumptions!D8)-MONTH(Assumptions!B22))+1,IF(MONTH(Assumptions!B22)=MONTH(Assumptions!D8),1,""))),IF(AND(J20="",YEAR(Assumptions!B22)+1=K19),((MONTH(K18)+12)-MONTH(Assumptions!B22))+1,IF(YEAR($B$6)=K19,$B$13-SUM($B$20:J20),IF(K19<YEAR(Assumptions!B22),"",IF(K19<YEAR($B$6),12,IF(K19>YEAR($B$6),"")))))) | L20: =IF(YEAR(Assumptions!B22)=L19,IF(MONTH(Assumptions!D8)=12,12-MONTH(Assumptions!B22)+1,IF(MONTH(Assumptions!B22)<MONTH(Assumptions!D8),(MONTH(Assumptions!D8)-MONTH(Assumptions!B22))+1,IF(MONTH(Assumptions!B22)=MONTH(Assumptions!D8),1,""))),IF(AND(K20="",YEAR(Assumptions!B22)+1=L19),((MONTH(L18)+12)-MONTH(Assumptions!B22))+1,IF(YEAR($B$6)=L19,$B$13-SUM($B$20:K20),IF(L19<YEAR(Assumptions!B22),"",IF(L19<YEAR($B$6),12,IF(L19>YEAR($B$6),"")))))) | M20: =IF(YEAR(Assumptions!B22)=M19,IF(MONTH(Assumptions!D8)=12,12-MONTH(Assumptions!B22)+1,IF(MONTH(Assumptions!B22)<MONTH(Assumptions!D8),(MONTH(Assumptions!D8)-MONTH(Assumptions!B22))+1,IF(MONTH(Assumptions!B22)=MONTH(Assumptions!D8),1,""))),IF(AND(L20="",YEAR(Assumptions!B22)+1=M19),((MONTH(M18)+12)-MONTH(Assumptions!B22))+1,IF(YEAR($B$6)=M19,$B$13-SUM($B$20:L20),IF(M19<YEAR(Assumptions!B22),"",IF(M19<YEAR($B$6),12,IF(M19>YEAR($B$6),"")))))) | N20: =IF(YEAR(Assumptions!B22)=N19,IF(MONTH(Assumptions!D8)=12,12-MONTH(Assumptions!B22)+1,IF(MONTH(Assumptions!B22)<MONTH(Assumptions!D8),(MONTH(Assumptions!D8)-MONTH(Assumptions!B22))+1,IF(MONTH(Assumptions!B22)=MONTH(Assumptions!D8),1,""))),IF(AND(M20="",YEAR(Assumptions!B22)+1=N19),((MONTH(N18)+12)-MONTH(Assumptions!B22))+1,IF(YEAR($B$6)=N19,$B$13-SUM($B$20:M20),IF(N19<YEAR(Assumptions!B22),"",IF(N19<YEAR($B$6),12,IF(N19>YEAR($B$6),"")))))) | O20: =IF(YEAR(Assumptions!B22)=O19,IF(MONTH(Assumptions!D8)=12,12-MONTH(Assumptions!B22)+1,IF(MONTH(Assumptions!B22)<MONTH(Assumptions!D8),(MONTH(Assumptions!D8)-MONTH(Assumptions!B22))+1,IF(MONTH(Assumptions!B22)=MONTH(Assumptions!D8),1,""))),IF(AND(N20="",YEAR(Assumptions!B22)+1=O19),((MONTH(O18)+12)-MONTH(Assumptions!B22))+1,IF(YEAR($B$6)=O19,$B$13-SUM($B$20:N20),IF(O19<YEAR(Assumptions!B22),"",IF(O19<YEAR($B$6),12,IF(O19>YEAR($B$6),"")))))) | P20: =IF(YEAR(Assumptions!B22)=P19,IF(MONTH(Assumptions!D8)=12,12-MONTH(Assumptions!B22)+1,IF(MONTH(Assumptions!B22)<MONTH(Assumptions!D8),(MONTH(Assumptions!D8)-MONTH(Assumptions!B22))+1,IF(MONTH(Assumptions!B22)=MONTH(Assumptions!D8),1,""))),IF(AND(O20="",YEAR(Assumptions!B22)+1=P19),((MONTH(P18)+12)-MONTH(Assumptions!B22))+1,IF(YEAR($B$6)=P19,$B$13-SUM($B$20:O20),IF(P19<YEAR(Assumptions!B22),"",IF(P19<YEAR($B$6),12,IF(P19>YEAR($B$6),""))))))
A21: Loan | B21: =IF(YEAR(Assumptions!B32)=B19,IF(MONTH(Assumptions!D8)=12,MONTH(Assumptions!B32),IF(MONTH(Assumptions!B32)<MONTH(Assumptions!D8),12-((MONTH(Assumptions!D8)-MONTH(Assumptions!B32))),IF(MONTH(Assumptions!B32)=MONTH(Assumptions!D8),1,IF(MONTH(Assumptions!B32)>MONTH(Assumptions!D8),IF(YEAR(Assumptions!B32)+1=B19,(MONTH(Assumptions!B32)-MONTH(B17))+1,""),"")))),IF(YEAR(Assumptions!B32)+1=B19,(MONTH(Assumptions!B32)-MONTH(B17))+1,"")) | C21: =IF(B21="",IF(YEAR(Assumptions!B32)=C19,IF(MONTH(Assumptions!D8)=12,MONTH(Assumptions!B32),IF(MONTH(Assumptions!B32)<MONTH(Assumptions!D8),12-((MONTH(Assumptions!D8)-MONTH(Assumptions!B32))),IF(MONTH(Assumptions!B32)=MONTH(Assumptions!D8),1,IF(MONTH(Assumptions!B32)>MONTH(Assumptions!D8),IF(YEAR(Assumptions!B32)+1=C19,(MONTH(Assumptions!B32)-MONTH(C17))+1,""),"")))),IF(YEAR(Assumptions!B32)+1=C19,(MONTH(Assumptions!B32)-MONTH(C17))+1,"")),"") | D21: =IF(C21="",IF(YEAR(Assumptions!B32)=D19,IF(MONTH(Assumptions!D8)=12,MONTH(Assumptions!B32),IF(MONTH(Assumptions!B32)<MONTH(Assumptions!D8),12-((MONTH(Assumptions!D8)-MONTH(Assumptions!B32))),IF(MONTH(Assumptions!B32)=MONTH(Assumptions!D8),1,IF(MONTH(Assumptions!B32)>MONTH(Assumptions!D8),IF(YEAR(Assumptions!B32)+1=D19,(MONTH(Assumptions!B32)-MONTH(D17))+1,""),"")))),IF(YEAR(Assumptions!B32)+1=D19,(MONTH(Assumptions!B32)-MONTH(D17))+1,"")),"") | E21: =IF(D21="",IF(YEAR(Assumptions!B32)=E19,IF(MONTH(Assumptions!D8)=12,MONTH(Assumptions!B32),IF(MONTH(Assumptions!B32)<MONTH(Assumptions!D8),12-((MONTH(Assumptions!D8)-MONTH(Assumptions!B32))),IF(MONTH(Assumptions!B32)=MONTH(Assumptions!D8),1,IF(MONTH(Assumptions!B32)>MONTH(Assumptions!D8),IF(YEAR(Assumptions!B32)+1=E19,(MONTH(Assumptions!B32)-MONTH(E17))+1,""),"")))),IF(YEAR(Assumptions!B32)+1=E19,(MONTH(Assumptions!B32)-MONTH(E17))+1,"")),"") | F21: =IF(E21="",IF(YEAR(Assumptions!B32)=F19,IF(MONTH(Assumptions!D8)=12,MONTH(Assumptions!B32),IF(MONTH(Assumptions!B32)<MONTH(Assumptions!D8),12-((MONTH(Assumptions!D8)-MONTH(Assumptions!B32))),IF(MONTH(Assumptions!B32)=MONTH(Assumptions!D8),1,IF(MONTH(Assumptions!B32)>MONTH(Assumptions!D8),IF(YEAR(Assumptions!B32)+1=F19,(MONTH(Assumptions!B32)-MONTH(F17))+1,""),"")))),IF(YEAR(Assumptions!B32)+1=F19,(MONTH(Assumptions!B32)-MONTH(F17))+1,"")),"") | G21: =IF(F21="",IF(YEAR(Assumptions!B32)=G19,IF(MONTH(Assumptions!D8)=12,MONTH(Assumptions!B32),IF(MONTH(Assumptions!B32)<MONTH(Assumptions!D8),12-((MONTH(Assumptions!D8)-MONTH(Assumptions!B32))),IF(MONTH(Assumptions!B32)=MONTH(Assumptions!D8),1,IF(MONTH(Assumptions!B32)>MONTH(Assumptions!D8),IF(YEAR(Assumptions!B32)+1=G19,(MONTH(Assumptions!B32)-MONTH(G17))+1,""),"")))),IF(YEAR(Assumptions!B32)+1=G19,(MONTH(Assumptions!B32)-MONTH(G17))+1,"")),"") | H21: =IF(G21="",IF(YEAR(Assumptions!B32)=H19,IF(MONTH(Assumptions!D8)=12,MONTH(Assumptions!B32),IF(MONTH(Assumptions!B32)<MONTH(Assumptions!D8),12-((MONTH(Assumptions!D8)-MONTH(Assumptions!B32))),IF(MONTH(Assumptions!B32)=MONTH(Assumptions!D8),1,IF(MONTH(Assumptions!B32)>MONTH(Assumptions!D8),IF(YEAR(Assumptions!B32)+1=H19,(MONTH(Assumptions!B32)-MONTH(H17))+1,""),"")))),IF(YEAR(Assumptions!B32)+1=H19,(MONTH(Assumptions!B32)-MONTH(H17))+1,"")),"") | I21: =IF(H21="",IF(YEAR(Assumptions!B32)=I19,IF(MONTH(Assumptions!D8)=12,MONTH(Assumptions!B32),IF(MONTH(Assumptions!B32)<MONTH(Assumptions!D8),12-((MONTH(Assumptions!D8)-MONTH(Assumptions!B32))),IF(MONTH(Assumptions!B32)=MONTH(Assumptions!D8),1,IF(MONTH(Assumptions!B32)>MONTH(Assumptions!D8),IF(YEAR(Assumptions!B32)+1=I19,(MONTH(Assumptions!B32)-MONTH(I17))+1,""),"")))),IF(YEAR(Assumptions!B32)+1=I19,(MONTH(Assumptions!B32)-MONTH(I17))+1,"")),"") | J21: =IF(I21="",IF(YEAR(Assumptions!B32)=J19,IF(MONTH(Assumptions!D8)=12,MONTH(Assumptions!B32),IF(MONTH(Assumptions!B32)<MONTH(Assumptions!D8),12-((MONTH(Assumptions!D8)-MONTH(Assumptions!B32))),IF(MONTH(Assumptions!B32)=MONTH(Assumptions!D8),1,IF(MONTH(Assumptions!B32)>MONTH(Assumptions!D8),IF(YEAR(Assumptions!B32)+1=J19,(MONTH(Assumptions!B32)-MONTH(J17))+1,""),"")))),IF(YEAR(Assumptions!B32)+1=J19,(MONTH(Assumptions!B32)-MONTH(J17))+1,"")),"") | K21: =IF(J21="",IF(YEAR(Assumptions!B32)=K19,IF(MONTH(Assumptions!D8)=12,MONTH(Assumptions!B32),IF(MONTH(Assumptions!B32)<MONTH(Assumptions!D8),12-((MONTH(Assumptions!D8)-MONTH(Assumptions!B32))),IF(MONTH(Assumptions!B32)=MONTH(Assumptions!D8),1,IF(MONTH(Assumptions!B32)>MONTH(Assumptions!D8),IF(YEAR(Assumptions!B32)+1=K19,(MONTH(Assumptions!B32)-MONTH(K17))+1,""),"")))),IF(YEAR(Assumptions!B32)+1=K19,(MONTH(Assumptions!B32)-MONTH(K17))+1,"")),"") | L21: =IF(K21="",IF(YEAR(Assumptions!B32)=L19,IF(MONTH(Assumptions!D8)=12,MONTH(Assumptions!B32),IF(MONTH(Assumptions!B32)<MONTH(Assumptions!D8),12-((MONTH(Assumptions!D8)-MONTH(Assumptions!B32))),IF(MONTH(Assumptions!B32)=MONTH(Assumptions!D8),1,IF(MONTH(Assumptions!B32)>MONTH(Assumptions!D8),IF(YEAR(Assumptions!B32)+1=L19,(MONTH(Assumptions!B32)-MONTH(L17))+1,""),"")))),IF(YEAR(Assumptions!B32)+1=L19,(MONTH(Assumptions!B32)-MONTH(L17))+1,"")),"") | M21: =IF(L21="",IF(YEAR(Assumptions!B32)=M19,IF(MONTH(Assumptions!D8)=12,MONTH(Assumptions!B32),IF(MONTH(Assumptions!B32)<MONTH(Assumptions!D8),12-((MONTH(Assumptions!D8)-MONTH(Assumptions!B32))),IF(MONTH(Assumptions!B32)=MONTH(Assumptions!D8),1,IF(MONTH(Assumptions!B32)>MONTH(Assumptions!D8),IF(YEAR(Assumptions!B32)+1=M19,(MONTH(Assumptions!B32)-MONTH(M17))+1,""),"")))),IF(YEAR(Assumptions!B32)+1=M19,(MONTH(Assumptions!B32)-MONTH(M17))+1,"")),"") | N21: =IF(M21="",IF(YEAR(Assumptions!B32)=N19,IF(MONTH(Assumptions!D8)=12,MONTH(Assumptions!B32),IF(MONTH(Assumptions!B32)<MONTH(Assumptions!D8),12-((MONTH(Assumptions!D8)-MONTH(Assumptions!B32))),IF(MONTH(Assumptions!B32)=MONTH(Assumptions!D8),1,IF(MONTH(Assumptions!B32)>MONTH(Assumptions!D8),IF(YEAR(Assumptions!B32)+1=N19,(MONTH(Assumptions!B32)-MONTH(N17))+1,""),"")))),IF(YEAR(Assumptions!B32)+1=N19,(MONTH(Assumptions!B32)-MONTH(N17))+1,"")),"") | O21: =IF(N21="",IF(YEAR(Assumptions!B32)=O19,IF(MONTH(Assumptions!D8)=12,MONTH(Assumptions!B32),IF(MONTH(Assumptions!B32)<MONTH(Assumptions!D8),12-((MONTH(Assumptions!D8)-MONTH(Assumptions!B32))),IF(MONTH(Assumptions!B32)=MONTH(Assumptions!D8),1,IF(MONTH(Assumptions!B32)>MONTH(Assumptions!D8),IF(YEAR(Assumptions!B32)+1=O19,(MONTH(Assumptions!B32)-MONTH(O17))+1,""),"")))),IF(YEAR(Assumptions!B32)+1=O19,(MONTH(Assumptions!B32)-MONTH(O17))+1,"")),"") | P21: =IF(O21="",IF(YEAR(Assumptions!B32)=P19,IF(MONTH(Assumptions!D8)=12,MONTH(Assumptions!B32),IF(MONTH(Assumptions!B32)<MONTH(Assumptions!D8),12-((MONTH(Assumptions!D8)-MONTH(Assumptions!B32))),IF(MONTH(Assumptions!B32)=MONTH(Assumptions!D8),1,IF(MONTH(Assumptions!B32)>MONTH(Assumptions!D8),IF(YEAR(Assumptions!B32)+1=P19,(MONTH(Assumptions!B32)-MONTH(P17))+1,""),"")))),IF(YEAR(Assumptions!B32)+1=P19,(MONTH(Assumptions!B32)-MONTH(P17))+1,"")),"")
A22: SA Fee | B22: =IF(YEAR(Assumptions!B22)=B19,IF(MONTH(Assumptions!D8)=12,1,IF(MONTH(Assumptions!B22)<MONTH(B17),1,"")),IF(A22="",IF(B19=YEAR(Assumptions!B22)+1,1,""),"")) | C22: =IF(YEAR(Assumptions!B22)=C19,IF(MONTH(Assumptions!D8)=12,1,IF(MONTH(Assumptions!B22)<MONTH(C17),1,"")),IF(B22="",IF(C19=YEAR(Assumptions!B22)+1,1,""),"")) | D22: =IF(YEAR(Assumptions!B22)=D19,IF(MONTH(Assumptions!D8)=12,1,IF(MONTH(Assumptions!B22)<MONTH(D17),1,"")),IF(C22="",IF(D19=YEAR(Assumptions!B22)+1,1,""),"")) | E22: =IF(YEAR(Assumptions!B22)=E19,IF(MONTH(Assumptions!D8)=12,1,IF(MONTH(Assumptions!B22)<MONTH(E17),1,"")),IF(D22="",IF(E19=YEAR(Assumptions!B22)+1,1,""),"")) | F22: =IF(YEAR(Assumptions!B22)=F19,IF(MONTH(Assumptions!D8)=12,1,IF(MONTH(Assumptions!B22)<MONTH(F17),1,"")),IF(E22="",IF(F19=YEAR(Assumptions!B22)+1,1,""),"")) | G22: =IF(YEAR(Assumptions!B22)=G19,IF(MONTH(Assumptions!D8)=12,1,IF(MONTH(Assumptions!B22)<MONTH(G17),1,"")),IF(F22="",IF(G19=YEAR(Assumptions!B22)+1,1,""),"")) | H22: =IF(YEAR(Assumptions!B22)=H19,IF(MONTH(Assumptions!D8)=12,1,IF(MONTH(Assumptions!B22)<MONTH(H17),1,"")),IF(G22="",IF(H19=YEAR(Assumptions!B22)+1,1,""),"")) | I22: =IF(YEAR(Assumptions!B22)=I19,IF(MONTH(Assumptions!D8)=12,1,IF(MONTH(Assumptions!B22)<MONTH(I17),1,"")),IF(H22="",IF(I19=YEAR(Assumptions!B22)+1,1,""),"")) | J22: =IF(YEAR(Assumptions!B22)=J19,IF(MONTH(Assumptions!D8)=12,1,IF(MONTH(Assumptions!B22)<MONTH(J17),1,"")),IF(I22="",IF(J19=YEAR(Assumptions!B22)+1,1,""),"")) | K22: =IF(YEAR(Assumptions!B22)=K19,IF(MONTH(Assumptions!D8)=12,1,IF(MONTH(Assumptions!B22)<MONTH(K17),1,"")),IF(J22="",IF(K19=YEAR(Assumptions!B22)+1,1,""),"")) | L22: =IF(YEAR(Assumptions!B22)=L19,IF(MONTH(Assumptions!D8)=12,1,IF(MONTH(Assumptions!B22)<MONTH(L17),1,"")),IF(K22="",IF(L19=YEAR(Assumptions!B22)+1,1,""),"")) | M22: =IF(YEAR(Assumptions!B22)=M19,IF(MONTH(Assumptions!D8)=12,1,IF(MONTH(Assumptions!B22)<MONTH(M17),1,"")),IF(L22="",IF(M19=YEAR(Assumptions!B22)+1,1,""),"")) | N22: =IF(YEAR(Assumptions!B22)=N19,IF(MONTH(Assumptions!D8)=12,1,IF(MONTH(Assumptions!B22)<MONTH(N17),1,"")),IF(M22="",IF(N19=YEAR(Assumptions!B22)+1,1,""),"")) | O22: =IF(YEAR(Assumptions!B22)=O19,IF(MONTH(Assumptions!D8)=12,1,IF(MONTH(Assumptions!B22)<MONTH(O17),1,"")),IF(N22="",IF(O19=YEAR(Assumptions!B22)+1,1,""),"")) | P22: =IF(YEAR(Assumptions!B22)=P19,IF(MONTH(Assumptions!D8)=12,1,IF(MONTH(Assumptions!B22)<MONTH(P17),1,"")),IF(O22="",IF(P19=YEAR(Assumptions!B22)+1,1,""),""))
A23: Loan Proceed | B23: =IF(YEAR(Assumptions!B32)=B19,IF(MONTH(Assumptions!D8)=12,1,IF(MONTH(Assumptions!B32)<MONTH(B17),1,"")),IF(A23="",IF(B19=YEAR(Assumptions!B32)+1,1,""),"")) | C23: =IF(YEAR(Assumptions!B32)=C19,IF(MONTH(Assumptions!D8)=12,1,IF(MONTH(Assumptions!B32)<MONTH(C17),1,"")),IF(B23="",IF(C19=YEAR(Assumptions!B32)+1,1,""),"")) | D23: =IF(YEAR(Assumptions!B32)=D19,IF(MONTH(Assumptions!D8)=12,1,IF(MONTH(Assumptions!B32)<MONTH(D17),1,"")),IF(C23="",IF(D19=YEAR(Assumptions!B32)+1,1,""),"")) | E23: =IF(YEAR(Assumptions!B32)=E19,IF(MONTH(Assumptions!D8)=12,1,IF(MONTH(Assumptions!B32)<MONTH(E17),1,"")),IF(D23="",IF(E19=YEAR(Assumptions!B32)+1,1,""),"")) | F23: =IF(YEAR(Assumptions!B32)=F19,IF(MONTH(Assumptions!D8)=12,1,IF(MONTH(Assumptions!B32)<MONTH(F17),1,"")),IF(E23="",IF(F19=YEAR(Assumptions!B32)+1,1,""),"")) | G23: =IF(YEAR(Assumptions!B32)=G19,IF(MONTH(Assumptions!D8)=12,1,IF(MONTH(Assumptions!B32)<MONTH(G17),1,"")),IF(F23="",IF(G19=YEAR(Assumptions!B32)+1,1,""),"")) | H23: =IF(YEAR(Assumptions!B32)=H19,IF(MONTH(Assumptions!D8)=12,1,IF(MONTH(Assumptions!B32)<MONTH(H17),1,"")),IF(G23="",IF(H19=YEAR(Assumptions!B32)+1,1,""),"")) | I23: =IF(YEAR(Assumptions!B32)=I19,IF(MONTH(Assumptions!D8)=12,1,IF(MONTH(Assumptions!B32)<MONTH(I17),1,"")),IF(H23="",IF(I19=YEAR(Assumptions!B32)+1,1,""),"")) | J23: =IF(YEAR(Assumptions!B32)=J19,IF(MONTH(Assumptions!D8)=12,1,IF(MONTH(Assumptions!B32)<MONTH(J17),1,"")),IF(I23="",IF(J19=YEAR(Assumptions!B32)+1,1,""),"")) | K23: =IF(YEAR(Assumptions!B32)=K19,IF(MONTH(Assumptions!D8)=12,1,IF(MONTH(Assumptions!B32)<MONTH(K17),1,"")),IF(J23="",IF(K19=YEAR(Assumptions!B32)+1,1,""),"")) | L23: =IF(YEAR(Assumptions!B32)=L19,IF(MONTH(Assumptions!D8)=12,1,IF(MONTH(Assumptions!B32)<MONTH(L17),1,"")),IF(K23="",IF(L19=YEAR(Assumptions!B32)+1,1,""),"")) | M23: =IF(YEAR(Assumptions!B32)=M19,IF(MONTH(Assumptions!D8)=12,1,IF(MONTH(Assumptions!B32)<MONTH(M17),1,"")),IF(L23="",IF(M19=YEAR(Assumptions!B32)+1,1,""),"")) | N23: =IF(YEAR(Assumptions!B32)=N19,IF(MONTH(Assumptions!D8)=12,1,IF(MONTH(Assumptions!B32)<MONTH(N17),1,"")),IF(M23="",IF(N19=YEAR(Assumptions!B32)+1,1,""),"")) | O23: =IF(YEAR(Assumptions!B32)=O19,IF(MONTH(Assumptions!D8)=12,1,IF(MONTH(Assumptions!B32)<MONTH(O17),1,"")),IF(N23="",IF(O19=YEAR(Assumptions!B32)+1,1,""),"")) | P23: =IF(YEAR(Assumptions!B32)=P19,IF(MONTH(Assumptions!D8)=12,1,IF(MONTH(Assumptions!B32)<MONTH(P17),1,"")),IF(O23="",IF(P19=YEAR(Assumptions!B32)+1,1,""),""))
F27: Assessments for Option 2
B29: =DATE(C32+1,B32,26) -> 26
B32: =MONTH(Assumptions!C23)-MONTH(Assumptions!D8) -> -11 | C32: =YEAR(Assumptions!C23) -> 1900 | D32: =MONTH(Assumptions!C23) -> 1 | E32: =DAY(Assumptions!C23) -> 0 | G32: =IF(B43="",1,B43) -> 0
B36: =Assumptions!C24*12 -> 0
A38: Loan Clac | B38: =IF((MONTH(B41)-MONTH(Assumptions!C32))+1=12,0,(MONTH(B41)-MONTH(Assumptions!C32))+1) -> 0 | C38: =IF((MONTH(C41)-MONTH(Assumptions!C32))+1=12,0,(MONTH(C41)-MONTH(Assumptions!C32))+1) -> 0 | D38: =IF((MONTH(D41)-MONTH(Assumptions!C32))+1=12,0,(MONTH(D41)-MONTH(Assumptions!C32))+1) -> 0 | E38: =IF((MONTH(E41)-MONTH(Assumptions!C32))+1=12,0,(MONTH(E41)-MONTH(Assumptions!C32))+1) -> 0 | F38: =IF((MONTH(F41)-MONTH(Assumptions!C32))+1=12,0,(MONTH(F41)-MONTH(Assumptions!C32))+1) -> 0 | G38: =IF((MONTH(G41)-MONTH(Assumptions!C32))+1=12,0,(MONTH(G41)-MONTH(Assumptions!C32))+1) -> 0 | H38: =IF((MONTH(H41)-MONTH(Assumptions!C32))+1=12,0,(MONTH(H41)-MONTH(Assumptions!C32))+1) -> 0 | I38: =IF((MONTH(I41)-MONTH(Assumptions!C32))+1=12,0,(MONTH(I41)-MONTH(Assumptions!C32))+1) -> 0 | J38: =IF((MONTH(J41)-MONTH(Assumptions!C32))+1=12,0,(MONTH(J41)-MONTH(Assumptions!C32))+1) -> 0 | K38: =IF((MONTH(K41)-MONTH(Assumptions!C32))+1=12,0,(MONTH(K41)-MONTH(Assumptions!C32))+1) -> 0 | L38: =IF((MONTH(L41)-MONTH(Assumptions!C32))+1=12,0,(MONTH(L41)-MONTH(Assumptions!C32))+1) -> 0 | M38: =IF((MONTH(M41)-MONTH(Assumptions!C32))+1=12,0,(MONTH(M41)-MONTH(Assumptions!C32))+1) -> 0 | N38: =IF((MONTH(N41)-MONTH(Assumptions!C32))+1=12,0,(MONTH(N41)-MONTH(Assumptions!C32))+1) -> 0 | O38: =IF((MONTH(O41)-MONTH(Assumptions!C32))+1=12,0,(MONTH(O41)-MONTH(Assumptions!C32))+1) -> 0 | P38: =IF((MONTH(P41)-MONTH(Assumptions!C32))+1=12,0,(MONTH(P41)-MONTH(Assumptions!C32))+1) -> 0
A39: SA Calc | B39: =IF((MONTH(B41)-MONTH(Assumptions!C22))+1=12,0,(MONTH(B41)-MONTH(Assumptions!C22))+1) -> 0 | C39: =IF((MONTH(C41)-MONTH(Assumptions!C22))+1=12,0,(MONTH(C41)-MONTH(Assumptions!C22))+1) -> 0 | D39: =IF((MONTH(D41)-MONTH(Assumptions!C22))+1=12,0,(MONTH(D41)-MONTH(Assumptions!C22))+1) -> 0 | E39: =IF((MONTH(E41)-MONTH(Assumptions!C22))+1=12,0,(MONTH(E41)-MONTH(Assumptions!C22))+1) -> 0 | F39: =IF((MONTH(F41)-MONTH(Assumptions!C22))+1=12,0,(MONTH(F41)-MONTH(Assumptions!C22))+1) -> 0 | G39: =IF((MONTH(G41)-MONTH(Assumptions!C22))+1=12,0,(MONTH(G41)-MONTH(Assumptions!C22))+1) -> 0 | H39: =IF((MONTH(H41)-MONTH(Assumptions!C22))+1=12,0,(MONTH(H41)-MONTH(Assumptions!C22))+1) -> 0 | I39: =IF((MONTH(I41)-MONTH(Assumptions!C22))+1=12,0,(MONTH(I41)-MONTH(Assumptions!C22))+1) -> 0 | J39: =IF((MONTH(J41)-MONTH(Assumptions!C22))+1=12,0,(MONTH(J41)-MONTH(Assumptions!C22))+1) -> 0 | K39: =IF((MONTH(K41)-MONTH(Assumptions!C22))+1=12,0,(MONTH(K41)-MONTH(Assumptions!C22))+1) -> 0 | L39: =IF((MONTH(L41)-MONTH(Assumptions!C22))+1=12,0,(MONTH(L41)-MONTH(Assumptions!C22))+1) -> 0 | M39: =IF((MONTH(M41)-MONTH(Assumptions!C22))+1=12,0,(MONTH(M41)-MONTH(Assumptions!C22))+1) -> 0 | N39: =IF((MONTH(N41)-MONTH(Assumptions!C22))+1=12,0,(MONTH(N41)-MONTH(Assumptions!C22))+1) -> 0 | O39: =IF((MONTH(O41)-MONTH(Assumptions!C22))+1=12,0,(MONTH(O41)-MONTH(Assumptions!C22))+1) -> 0 | P39: =IF((MONTH(P41)-MONTH(Assumptions!C22))+1=12,0,(MONTH(P41)-MONTH(Assumptions!C22))+1) -> 0
A40: Beg | B40: =DATE(B42,IF(MONTH(Assumptions!D8)=12,1,MONTH(Assumptions!D8)+1),1) -> 41275 | C40: =DATE(C42,IF(MONTH(Assumptions!D8)=12,1,MONTH(Assumptions!D8)+1),1) -> 41640 | D40: =DATE(D42,IF(MONTH(Assumptions!D8)=12,1,MONTH(Assumptions!D8)+1),1) -> 42005 | E40: =DATE(E42,IF(MONTH(Assumptions!D8)=12,1,MONTH(Assumptions!D8)+1),1) -> 42370 | F40: =DATE(F42,IF(MONTH(Assumptions!D8)=12,1,MONTH(Assumptions!D8)+1),1) -> 42736 | G40: =DATE(G42,IF(MONTH(Assumptions!D8)=12,1,MONTH(Assumptions!D8)+1),1) -> 43101 | H40: =DATE(H42,IF(MONTH(Assumptions!D8)=12,1,MONTH(Assumptions!D8)+1),1) -> 43466 | I40: =DATE(I42,IF(MONTH(Assumptions!D8)=12,1,MONTH(Assumptions!D8)+1),1) -> 43831 | J40: =DATE(J42,IF(MONTH(Assumptions!D8)=12,1,MONTH(Assumptions!D8)+1),1) -> 44197 | K40: =DATE(K42,IF(MONTH(Assumptions!D8)=12,1,MONTH(Assumptions!D8)+1),1) -> 44562 | L40: =DATE(L42,IF(MONTH(Assumptions!D8)=12,1,MONTH(Assumptions!D8)+1),1) -> 44927 | M40: =DATE(M42,IF(MONTH(Assumptions!D8)=12,1,MONTH(Assumptions!D8)+1),1) -> 45292 | N40: =DATE(N42,IF(MONTH(Assumptions!D8)=12,1,MONTH(Assumptions!D8)+1),1) -> 45658 | O40: =DATE(O42,IF(MONTH(Assumptions!D8)=12,1,MONTH(Assumptions!D8)+1),1) -> 46023 | P40: =DATE(P42,IF(MONTH(Assumptions!D8)=12,1,MONTH(Assumptions!D8)+1),1) -> 46388
A41: End | B41: =DATE(IF(MONTH(Assumptions!D8)=12,B42,B42+1),MONTH(Assumptions!D8),DAY(Assumptions!D8)) -> 41639 | C41: =DATE(IF(MONTH(Assumptions!D8)=12,C42,C42+1),MONTH(Assumptions!D8),DAY(Assumptions!D8)) -> 42004 | D41: =DATE(IF(MONTH(Assumptions!D8)=12,D42,D42+1),MONTH(Assumptions!D8),DAY(Assumptions!D8)) -> 42369 | E41: =DATE(IF(MONTH(Assumptions!D8)=12,E42,E42+1),MONTH(Assumptions!D8),DAY(Assumptions!D8)) -> 42735 | F41: =DATE(IF(MONTH(Assumptions!D8)=12,F42,F42+1),MONTH(Assumptions!D8),DAY(Assumptions!D8)) -> 43100 | G41: =DATE(IF(MONTH(Assumptions!D8)=12,G42,G42+1),MONTH(Assumptions!D8),DAY(Assumptions!D8)) -> 43465 | H41: =DATE(IF(MONTH(Assumptions!D8)=12,H42,H42+1),MONTH(Assumptions!D8),DAY(Assumptions!D8)) -> 43830 | I41: =DATE(IF(MONTH(Assumptions!D8)=12,I42,I42+1),MONTH(Assumptions!D8),DAY(Assumptions!D8)) -> 44196 | J41: =DATE(IF(MONTH(Assumptions!D8)=12,J42,J42+1),MONTH(Assumptions!D8),DAY(Assumptions!D8)) -> 44561 | K41: =DATE(IF(MONTH(Assumptions!D8)=12,K42,K42+1),MONTH(Assumptions!D8),DAY(Assumptions!D8)) -> 44926 | L41: =DATE(IF(MONTH(Assumptions!D8)=12,L42,L42+1),MONTH(Assumptions!D8),DAY(Assumptions!D8)) -> 45291 | M41: =DATE(IF(MONTH(Assumptions!D8)=12,M42,M42+1),MONTH(Assumptions!D8),DAY(Assumptions!D8)) -> 45657 | N41: =DATE(IF(MONTH(Assumptions!D8)=12,N42,N42+1),MONTH(Assumptions!D8),DAY(Assumptions!D8)) -> 46022 | O41: =DATE(IF(MONTH(Assumptions!D8)=12,O42,O42+1),MONTH(Assumptions!D8),DAY(Assumptions!D8)) -> 46387 | P41: =DATE(IF(MONTH(Assumptions!D8)=12,P42,P42+1),MONTH(Assumptions!D8),DAY(Assumptions!D8)) -> 46752
B42: =Assumptions!$D$7 -> 2013 | C42: =+B42+1 -> 2014 | D42: =+C42+1 -> 2015 | E42: =+D42+1 -> 2016 | F42: =+E42+1 -> 2017 | G42: =+F42+1 -> 2018 | H42: =+G42+1 -> 2019 | I42: =+H42+1 -> 2020 | J42: =+I42+1 -> 2021 | ... P42: =+O42+1 -> 2027
A43: SA Month | B43: =IF(YEAR(Assumptions!C22)=B42,IF(MONTH(Assumptions!D8)=12,12-MONTH(Assumptions!C22)+1,IF(MONTH(Assumptions!C22)<MONTH(Assumptions!D8),(MONTH(Assumptions!D8)-MONTH(Assumptions!C22))+1,IF(MONTH(Assumptions!C22)=MONTH(Assumptions!D8),1,""))),IF(AND(A43="",YEAR(Assumptions!C22)+1=B42),((MONTH(B41)+12)-MONTH(Assumptions!C22))+1,IF(YEAR($B$29)=B42,$B$36-SUM(A$43:$B43),IF(B42<YEAR(Assumptions!C22),0,IF(B42<YEAR($B$29),12,IF(B42>YEAR($B$29),0)))))) -> 0 | C43: =IF(YEAR(Assumptions!C22)=C42,IF(MONTH(Assumptions!D8)=12,12-MONTH(Assumptions!C22)+1,IF(MONTH(Assumptions!C22)<MONTH(Assumptions!D8),(MONTH(Assumptions!D8)-MONTH(Assumptions!C22))+1,IF(MONTH(Assumptions!C22)=MONTH(Assumptions!D8),1,""))),IF(AND(B43="",YEAR(Assumptions!C22)+1=C42),((MONTH(C41)+12)-MONTH(Assumptions!C22))+1,IF(YEAR($B$29)=C42,$B$36-SUM(B$43:$B43),IF(C42<YEAR(Assumptions!C22),"",IF(C42<YEAR($B$29),12,IF(C42>YEAR($B$29),"")))))) | D43: =IF(YEAR(Assumptions!C22)=D42,IF(MONTH(Assumptions!D8)=12,12-MONTH(Assumptions!C22)+1,IF(MONTH(Assumptions!C22)<MONTH(Assumptions!D8),(MONTH(Assumptions!D8)-MONTH(Assumptions!C22))+1,IF(MONTH(Assumptions!C22)=MONTH(Assumptions!D8),1,""))),IF(AND(C43="",YEAR(Assumptions!C22)+1=D42),((MONTH(D41)+12)-MONTH(Assumptions!C22))+1,IF(YEAR($B$29)=D42,$B$36-SUM($B$43:C43),IF(D42<YEAR(Assumptions!C22),"",IF(D42<YEAR($B$29),12,IF(D42>YEAR($B$29),"")))))) | E43: =IF(YEAR(Assumptions!C22)=E42,IF(MONTH(Assumptions!D8)=12,12-MONTH(Assumptions!C22)+1,IF(MONTH(Assumptions!C22)<MONTH(Assumptions!D8),(MONTH(Assumptions!D8)-MONTH(Assumptions!C22))+1,IF(MONTH(Assumptions!C22)=MONTH(Assumptions!D8),1,""))),IF(AND(D43="",YEAR(Assumptions!C22)+1=E42),((MONTH(E41)+12)-MONTH(Assumptions!C22))+1,IF(YEAR($B$29)=E42,$B$36-SUM($B$43:D43),IF(E42<YEAR(Assumptions!C22),"",IF(E42<YEAR($B$29),12,IF(E42>YEAR($B$29),"")))))) | F43: =IF(YEAR(Assumptions!C22)=F42,IF(MONTH(Assumptions!D8)=12,12-MONTH(Assumptions!C22)+1,IF(MONTH(Assumptions!C22)<MONTH(Assumptions!D8),(MONTH(Assumptions!D8)-MONTH(Assumptions!C22))+1,IF(MONTH(Assumptions!C22)=MONTH(Assumptions!D8),1,""))),IF(AND(E43="",YEAR(Assumptions!C22)+1=F42),((MONTH(F41)+12)-MONTH(Assumptions!C22))+1,IF(YEAR($B$29)=F42,$B$36-SUM($B$43:E43),IF(F42<YEAR(Assumptions!C22),"",IF(F42<YEAR($B$29),12,IF(F42>YEAR($B$29),"")))))) | G43: =IF(YEAR(Assumptions!C22)=G42,IF(MONTH(Assumptions!D8)=12,12-MONTH(Assumptions!C22)+1,IF(MONTH(Assumptions!C22)<MONTH(Assumptions!D8),(MONTH(Assumptions!D8)-MONTH(Assumptions!C22))+1,IF(MONTH(Assumptions!C22)=MONTH(Assumptions!D8),1,""))),IF(AND(F43="",YEAR(Assumptions!C22)+1=G42),((MONTH(G41)+12)-MONTH(Assumptions!C22))+1,IF(YEAR($B$29)=G42,$B$36-SUM($B$43:F43),IF(G42<YEAR(Assumptions!C22),"",IF(G42<YEAR($B$29),12,IF(G42>YEAR($B$29),"")))))) | H43: =IF(YEAR(Assumptions!C22)=H42,IF(MONTH(Assumptions!D8)=12,12-MONTH(Assumptions!C22)+1,IF(MONTH(Assumptions!C22)<MONTH(Assumptions!D8),(MONTH(Assumptions!D8)-MONTH(Assumptions!C22))+1,IF(MONTH(Assumptions!C22)=MONTH(Assumptions!D8),1,""))),IF(AND(G43="",YEAR(Assumptions!C22)+1=H42),((MONTH(H41)+12)-MONTH(Assumptions!C22))+1,IF(YEAR($B$29)=H42,$B$36-SUM($B$43:G43),IF(H42<YEAR(Assumptions!C22),"",IF(H42<YEAR($B$29),12,IF(H42>YEAR($B$29),"")))))) | I43: =IF(YEAR(Assumptions!C22)=I42,IF(MONTH(Assumptions!D8)=12,12-MONTH(Assumptions!C22)+1,IF(MONTH(Assumptions!C22)<MONTH(Assumptions!D8),(MONTH(Assumptions!D8)-MONTH(Assumptions!C22))+1,IF(MONTH(Assumptions!C22)=MONTH(Assumptions!D8),1,""))),IF(AND(H43="",YEAR(Assumptions!C22)+1=I42),((MONTH(I41)+12)-MONTH(Assumptions!C22))+1,IF(YEAR($B$29)=I42,$B$36-SUM($B$43:H43),IF(I42<YEAR(Assumptions!C22),"",IF(I42<YEAR($B$29),12,IF(I42>YEAR($B$29),"")))))) | J43: =IF(YEAR(Assumptions!C22)=J42,IF(MONTH(Assumptions!D8)=12,12-MONTH(Assumptions!C22)+1,IF(MONTH(Assumptions!C22)<MONTH(Assumptions!D8),(MONTH(Assumptions!D8)-MONTH(Assumptions!C22))+1,IF(MONTH(Assumptions!C22)=MONTH(Assumptions!D8),1,""))),IF(AND(I43="",YEAR(Assumptions!C22)+1=J42),((MONTH(J41)+12)-MONTH(Assumptions!C22))+1,IF(YEAR($B$29)=J42,$B$36-SUM($B$43:I43),IF(J42<YEAR(Assumptions!C22),"",IF(J42<YEAR($B$29),12,IF(J42>YEAR($B$29),"")))))) | K43: =IF(YEAR(Assumptions!C22)=K42,IF(MONTH(Assumptions!D8)=12,12-MONTH(Assumptions!C22)+1,IF(MONTH(Assumptions!C22)<MONTH(Assumptions!D8),(MONTH(Assumptions!D8)-MONTH(Assumptions!C22))+1,IF(MONTH(Assumptions!C22)=MONTH(Assumptions!D8),1,""))),IF(AND(J43="",YEAR(Assumptions!C22)+1=K42),((MONTH(K41)+12)-MONTH(Assumptions!C22))+1,IF(YEAR($B$29)=K42,$B$36-SUM($B$43:J43),IF(K42<YEAR(Assumptions!C22),"",IF(K42<YEAR($B$29),12,IF(K42>YEAR($B$29),"")))))) | L43: =IF(YEAR(Assumptions!C22)=L42,IF(MONTH(Assumptions!D8)=12,12-MONTH(Assumptions!C22)+1,IF(MONTH(Assumptions!C22)<MONTH(Assumptions!D8),(MONTH(Assumptions!D8)-MONTH(Assumptions!C22))+1,IF(MONTH(Assumptions!C22)=MONTH(Assumptions!D8),1,""))),IF(AND(K43="",YEAR(Assumptions!C22)+1=L42),((MONTH(L41)+12)-MONTH(Assumptions!C22))+1,IF(YEAR($B$29)=L42,$B$36-SUM($B$43:K43),IF(L42<YEAR(Assumptions!C22),"",IF(L42<YEAR($B$29),12,IF(L42>YEAR($B$29),"")))))) | M43: =IF(YEAR(Assumptions!C22)=M42,IF(MONTH(Assumptions!D8)=12,12-MONTH(Assumptions!C22)+1,IF(MONTH(Assumptions!C22)<MONTH(Assumptions!D8),(MONTH(Assumptions!D8)-MONTH(Assumptions!C22))+1,IF(MONTH(Assumptions!C22)=MONTH(Assumptions!D8),1,""))),IF(AND(L43="",YEAR(Assumptions!C22)+1=M42),((MONTH(M41)+12)-MONTH(Assumptions!C22))+1,IF(YEAR($B$29)=M42,$B$36-SUM($B$43:L43),IF(M42<YEAR(Assumptions!C22),"",IF(M42<YEAR($B$29),12,IF(M42>YEAR($B$29),"")))))) | N43: =IF(YEAR(Assumptions!C22)=N42,IF(MONTH(Assumptions!D8)=12,12-MONTH(Assumptions!C22)+1,IF(MONTH(Assumptions!C22)<MONTH(Assumptions!D8),(MONTH(Assumptions!D8)-MONTH(Assumptions!C22))+1,IF(MONTH(Assumptions!C22)=MONTH(Assumptions!D8),1,""))),IF(AND(M43="",YEAR(Assumptions!C22)+1=N42),((MONTH(N41)+12)-MONTH(Assumptions!C22))+1,IF(YEAR($B$29)=N42,$B$36-SUM($B$43:M43),IF(N42<YEAR(Assumptions!C22),"",IF(N42<YEAR($B$29),12,IF(N42>YEAR($B$29),"")))))) | O43: =IF(YEAR(Assumptions!C22)=O42,IF(MONTH(Assumptions!D8)=12,12-MONTH(Assumptions!C22)+1,IF(MONTH(Assumptions!C22)<MONTH(Assumptions!D8),(MONTH(Assumptions!D8)-MONTH(Assumptions!C22))+1,IF(MONTH(Assumptions!C22)=MONTH(Assumptions!D8),1,""))),IF(AND(N43="",YEAR(Assumptions!C22)+1=O42),((MONTH(O41)+12)-MONTH(Assumptions!C22))+1,IF(YEAR($B$29)=O42,$B$36-SUM($B$43:N43),IF(O42<YEAR(Assumptions!C22),"",IF(O42<YEAR($B$29),12,IF(O42>YEAR($B$29),"")))))) | P43: =IF(YEAR(Assumptions!C22)=P42,IF(MONTH(Assumptions!D8)=12,12-MONTH(Assumptions!C22)+1,IF(MONTH(Assumptions!C22)<MONTH(Assumptions!D8),(MONTH(Assumptions!D8)-MONTH(Assumptions!C22))+1,IF(MONTH(Assumptions!C22)=MONTH(Assumptions!D8),1,""))),IF(AND(O43="",YEAR(Assumptions!C22)+1=P42),((MONTH(P41)+12)-MONTH(Assumptions!C22))+1,IF(YEAR($B$29)=P42,$B$36-SUM($B$43:O43),IF(P42<YEAR(Assumptions!C22),"",IF(P42<YEAR($B$29),12,IF(P42>YEAR($B$29),""))))))
A44: Loan | B44: =IF(YEAR(Assumptions!C32)=B42,IF(MONTH(Assumptions!D8)=12,MONTH(Assumptions!C32),IF(MONTH(Assumptions!C32)<MONTH(Assumptions!D8),12-((MONTH(Assumptions!D8)-MONTH(Assumptions!C32))),IF(MONTH(Assumptions!C32)=MONTH(Assumptions!D8),1,IF(MONTH(Assumptions!C32)>MONTH(Assumptions!D8),IF(YEAR(Assumptions!C32)+1=B42,(MONTH(Assumptions!C32)-MONTH(B40))+1,""),"")))),IF(YEAR(Assumptions!C32)+1=B42,(MONTH(Assumptions!C32)-MONTH(B40))+1,"")) | C44: =IF(B44="",IF(YEAR(Assumptions!C32)=C42,IF(MONTH(Assumptions!D8)=12,MONTH(Assumptions!C32),IF(MONTH(Assumptions!C32)<MONTH(Assumptions!D8),12-((MONTH(Assumptions!D8)-MONTH(Assumptions!C32))),IF(MONTH(Assumptions!C32)=MONTH(Assumptions!D8),1,IF(MONTH(Assumptions!C32)>MONTH(Assumptions!D8),IF(YEAR(Assumptions!C32)+1=C42,(MONTH(Assumptions!C32)-MONTH(C40))+1,""),"")))),IF(YEAR(Assumptions!C32)+1=C42,(MONTH(Assumptions!C32)-MONTH(C40))+1,"")),"") | D44: =IF(C44="",IF(YEAR(Assumptions!C32)=D42,IF(MONTH(Assumptions!D8)=12,MONTH(Assumptions!C32),IF(MONTH(Assumptions!C32)<MONTH(Assumptions!D8),12-((MONTH(Assumptions!D8)-MONTH(Assumptions!C32))),IF(MONTH(Assumptions!C32)=MONTH(Assumptions!D8),1,IF(MONTH(Assumptions!C32)>MONTH(Assumptions!D8),IF(YEAR(Assumptions!C32)+1=D42,(MONTH(Assumptions!C32)-MONTH(D40))+1,""),"")))),IF(YEAR(Assumptions!C32)+1=D42,(MONTH(Assumptions!C32)-MONTH(D40))+1,"")),"") | E44: =IF(D44="",IF(YEAR(Assumptions!C32)=E42,IF(MONTH(Assumptions!D8)=12,MONTH(Assumptions!C32),IF(MONTH(Assumptions!C32)<MONTH(Assumptions!D8),12-((MONTH(Assumptions!D8)-MONTH(Assumptions!C32))),IF(MONTH(Assumptions!C32)=MONTH(Assumptions!D8),1,IF(MONTH(Assumptions!C32)>MONTH(Assumptions!D8),IF(YEAR(Assumptions!C32)+1=E42,(MONTH(Assumptions!C32)-MONTH(E40))+1,""),"")))),IF(YEAR(Assumptions!C32)+1=E42,(MONTH(Assumptions!C32)-MONTH(E40))+1,"")),"") | F44: =IF(E44="",IF(YEAR(Assumptions!C32)=F42,IF(MONTH(Assumptions!D8)=12,MONTH(Assumptions!C32),IF(MONTH(Assumptions!C32)<MONTH(Assumptions!D8),12-((MONTH(Assumptions!D8)-MONTH(Assumptions!C32))),IF(MONTH(Assumptions!C32)=MONTH(Assumptions!D8),1,IF(MONTH(Assumptions!C32)>MONTH(Assumptions!D8),IF(YEAR(Assumptions!C32)+1=F42,(MONTH(Assumptions!C32)-MONTH(F40))+1,""),"")))),IF(YEAR(Assumptions!C32)+1=F42,(MONTH(Assumptions!C32)-MONTH(F40))+1,"")),"") | G44: =IF(F44="",IF(YEAR(Assumptions!C32)=G42,IF(MONTH(Assumptions!D8)=12,MONTH(Assumptions!C32),IF(MONTH(Assumptions!C32)<MONTH(Assumptions!D8),12-((MONTH(Assumptions!D8)-MONTH(Assumptions!C32))),IF(MONTH(Assumptions!C32)=MONTH(Assumptions!D8),1,IF(MONTH(Assumptions!C32)>MONTH(Assumptions!D8),IF(YEAR(Assumptions!C32)+1=G42,(MONTH(Assumptions!C32)-MONTH(G40))+1,""),"")))),IF(YEAR(Assumptions!C32)+1=G42,(MONTH(Assumptions!C32)-MONTH(G40))+1,"")),"") -> 1 | H44: =IF(G44="",IF(YEAR(Assumptions!C32)=H42,IF(MONTH(Assumptions!D8)=12,MONTH(Assumptions!C32),IF(MONTH(Assumptions!C32)<MONTH(Assumptions!D8),12-((MONTH(Assumptions!D8)-MONTH(Assumptions!C32))),IF(MONTH(Assumptions!C32)=MONTH(Assumptions!D8),1,IF(MONTH(Assumptions!C32)>MONTH(Assumptions!D8),IF(YEAR(Assumptions!C32)+1=H42,(MONTH(Assumptions!C32)-MONTH(H40))+1,""),"")))),IF(YEAR(Assumptions!C32)+1=H42,(MONTH(Assumptions!C32)-MONTH(H40))+1,"")),"") | I44: =IF(H44="",IF(YEAR(Assumptions!C32)=I42,IF(MONTH(Assumptions!D8)=12,MONTH(Assumptions!C32),IF(MONTH(Assumptions!C32)<MONTH(Assumptions!D8),12-((MONTH(Assumptions!D8)-MONTH(Assumptions!C32))),IF(MONTH(Assumptions!C32)=MONTH(Assumptions!D8),1,IF(MONTH(Assumptions!C32)>MONTH(Assumptions!D8),IF(YEAR(Assumptions!C32)+1=I42,(MONTH(Assumptions!C32)-MONTH(I40))+1,""),"")))),IF(YEAR(Assumptions!C32)+1=I42,(MONTH(Assumptions!C32)-MONTH(I40))+1,"")),"") | J44: =IF(I44="",IF(YEAR(Assumptions!C32)=J42,IF(MONTH(Assumptions!D8)=12,MONTH(Assumptions!C32),IF(MONTH(Assumptions!C32)<MONTH(Assumptions!D8),12-((MONTH(Assumptions!D8)-MONTH(Assumptions!C32))),IF(MONTH(Assumptions!C32)=MONTH(Assumptions!D8),1,IF(MONTH(Assumptions!C32)>MONTH(Assumptions!D8),IF(YEAR(Assumptions!C32)+1=J42,(MONTH(Assumptions!C32)-MONTH(J40))+1,""),"")))),IF(YEAR(Assumptions!C32)+1=J42,(MONTH(Assumptions!C32)-MONTH(J40))+1,"")),"") | K44: =IF(J44="",IF(YEAR(Assumptions!C32)=K42,IF(MONTH(Assumptions!D8)=12,MONTH(Assumptions!C32),IF(MONTH(Assumptions!C32)<MONTH(Assumptions!D8),12-((MONTH(Assumptions!D8)-MONTH(Assumptions!C32))),IF(MONTH(Assumptions!C32)=MONTH(Assumptions!D8),1,IF(MONTH(Assumptions!C32)>MONTH(Assumptions!D8),IF(YEAR(Assumptions!C32)+1=K42,(MONTH(Assumptions!C32)-MONTH(K40))+1,""),"")))),IF(YEAR(Assumptions!C32)+1=K42,(MONTH(Assumptions!C32)-MONTH(K40))+1,"")),"") | L44: =IF(K44="",IF(YEAR(Assumptions!C32)=L42,IF(MONTH(Assumptions!D8)=12,MONTH(Assumptions!C32),IF(MONTH(Assumptions!C32)<MONTH(Assumptions!D8),12-((MONTH(Assumptions!D8)-MONTH(Assumptions!C32))),IF(MONTH(Assumptions!C32)=MONTH(Assumptions!D8),1,IF(MONTH(Assumptions!C32)>MONTH(Assumptions!D8),IF(YEAR(Assumptions!C32)+1=L42,(MONTH(Assumptions!C32)-MONTH(L40))+1,""),"")))),IF(YEAR(Assumptions!C32)+1=L42,(MONTH(Assumptions!C32)-MONTH(L40))+1,"")),"") | M44: =IF(L44="",IF(YEAR(Assumptions!C32)=M42,IF(MONTH(Assumptions!D8)=12,MONTH(Assumptions!C32),IF(MONTH(Assumptions!C32)<MONTH(Assumptions!D8),12-((MONTH(Assumptions!D8)-MONTH(Assumptions!C32))),IF(MONTH(Assumptions!C32)=MONTH(Assumptions!D8),1,IF(MONTH(Assumptions!C32)>MONTH(Assumptions!D8),IF(YEAR(Assumptions!C32)+1=M42,(MONTH(Assumptions!C32)-MONTH(M40))+1,""),"")))),IF(YEAR(Assumptions!C32)+1=M42,(MONTH(Assumptions!C32)-MONTH(M40))+1,"")),"") | N44: =IF(M44="",IF(YEAR(Assumptions!C32)=N42,IF(MONTH(Assumptions!D8)=12,MONTH(Assumptions!C32),IF(MONTH(Assumptions!C32)<MONTH(Assumptions!D8),12-((MONTH(Assumptions!D8)-MONTH(Assumptions!C32))),IF(MONTH(Assumptions!C32)=MONTH(Assumptions!D8),1,IF(MONTH(Assumptions!C32)>MONTH(Assumptions!D8),IF(YEAR(Assumptions!C32)+1=N42,(MONTH(Assumptions!C32)-MONTH(N40))+1,""),"")))),IF(YEAR(Assumptions!C32)+1=N42,(MONTH(Assumptions!C32)-MONTH(N40))+1,"")),"") | O44: =IF(N44="",IF(YEAR(Assumptions!C32)=O42,IF(MONTH(Assumptions!D8)=12,MONTH(Assumptions!C32),IF(MONTH(Assumptions!C32)<MONTH(Assumptions!D8),12-((MONTH(Assumptions!D8)-MONTH(Assumptions!C32))),IF(MONTH(Assumptions!C32)=MONTH(Assumptions!D8),1,IF(MONTH(Assumptions!C32)>MONTH(Assumptions!D8),IF(YEAR(Assumptions!C32)+1=O42,(MONTH(Assumptions!C32)-MONTH(O40))+1,""),"")))),IF(YEAR(Assumptions!C32)+1=O42,(MONTH(Assumptions!C32)-MONTH(O40))+1,"")),"") | P44: =IF(O44="",IF(YEAR(Assumptions!C32)=P42,IF(MONTH(Assumptions!D8)=12,MONTH(Assumptions!C32),IF(MONTH(Assumptions!C32)<MONTH(Assumptions!D8),12-((MONTH(Assumptions!D8)-MONTH(Assumptions!C32))),IF(MONTH(Assumptions!C32)=MONTH(Assumptions!D8),1,IF(MONTH(Assumptions!C32)>MONTH(Assumptions!D8),IF(YEAR(Assumptions!C32)+1=P42,(MONTH(Assumptions!C32)-MONTH(P40))+1,""),"")))),IF(YEAR(Assumptions!C32)+1=P42,(MONTH(Assumptions!C32)-MONTH(P40))+1,"")),"")
A45: SA Fee | B45: =IF(YEAR(Assumptions!C22)=B42,IF(MONTH(Assumptions!D8)=12,1,IF(MONTH(Assumptions!C22)<MONTH(B40),1,"")),IF(A45="",IF(B42=YEAR(Assumptions!C22)+1,1,""),"")) | C45: =IF(YEAR(Assumptions!C22)=C42,IF(MONTH(Assumptions!D8)=12,1,IF(MONTH(Assumptions!C22)<MONTH(C40),1,"")),IF(B45="",IF(C42=YEAR(Assumptions!C22)+1,1,""),"")) | D45: =IF(YEAR(Assumptions!C22)=D42,IF(MONTH(Assumptions!D8)=12,1,IF(MONTH(Assumptions!C22)<MONTH(D40),1,"")),IF(C45="",IF(D42=YEAR(Assumptions!C22)+1,1,""),"")) | E45: =IF(YEAR(Assumptions!C22)=E42,IF(MONTH(Assumptions!D8)=12,1,IF(MONTH(Assumptions!C22)<MONTH(E40),1,"")),IF(D45="",IF(E42=YEAR(Assumptions!C22)+1,1,""),"")) | F45: =IF(YEAR(Assumptions!C22)=F42,IF(MONTH(Assumptions!D8)=12,1,IF(MONTH(Assumptions!C22)<MONTH(F40),1,"")),IF(E45="",IF(F42=YEAR(Assumptions!C22)+1,1,""),"")) | G45: =IF(YEAR(Assumptions!C22)=G42,IF(MONTH(Assumptions!D8)=12,1,IF(MONTH(Assumptions!C22)<MONTH(G40),1,"")),IF(F45="",IF(G42=YEAR(Assumptions!C22)+1,1,""),"")) | H45: =IF(YEAR(Assumptions!C22)=H42,IF(MONTH(Assumptions!D8)=12,1,IF(MONTH(Assumptions!C22)<MONTH(H40),1,"")),IF(G45="",IF(H42=YEAR(Assumptions!C22)+1,1,""),"")) | I45: =IF(YEAR(Assumptions!C22)=I42,IF(MONTH(Assumptions!D8)=12,1,IF(MONTH(Assumptions!C22)<MONTH(I40),1,"")),IF(H45="",IF(I42=YEAR(Assumptions!C22)+1,1,""),"")) | J45: =IF(YEAR(Assumptions!C22)=J42,IF(MONTH(Assumptions!D8)=12,1,IF(MONTH(Assumptions!C22)<MONTH(J40),1,"")),IF(I45="",IF(J42=YEAR(Assumptions!C22)+1,1,""),"")) | K45: =IF(YEAR(Assumptions!C22)=K42,IF(MONTH(Assumptions!D8)=12,1,IF(MONTH(Assumptions!C22)<MONTH(K40),1,"")),IF(J45="",IF(K42=YEAR(Assumptions!C22)+1,1,""),"")) | L45: =IF(YEAR(Assumptions!C22)=L42,IF(MONTH(Assumptions!D8)=12,1,IF(MONTH(Assumptions!C22)<MONTH(L40),1,"")),IF(K45="",IF(L42=YEAR(Assumptions!C22)+1,1,""),"")) | M45: =IF(YEAR(Assumptions!C22)=M42,IF(MONTH(Assumptions!D8)=12,1,IF(MONTH(Assumptions!C22)<MONTH(M40),1,"")),IF(L45="",IF(M42=YEAR(Assumptions!C22)+1,1,""),"")) | N45: =IF(YEAR(Assumptions!C22)=N42,IF(MONTH(Assumptions!D8)=12,1,IF(MONTH(Assumptions!C22)<MONTH(N40),1,"")),IF(M45="",IF(N42=YEAR(Assumptions!C22)+1,1,""),"")) | O45: =IF(YEAR(Assumptions!C22)=O42,IF(MONTH(Assumptions!D8)=12,1,IF(MONTH(Assumptions!C22)<MONTH(O40),1,"")),IF(N45="",IF(O42=YEAR(Assumptions!C22)+1,1,""),"")) | P45: =IF(YEAR(Assumptions!C22)=P42,IF(MONTH(Assumptions!D8)=12,1,IF(MONTH(Assumptions!C22)<MONTH(P40),1,"")),IF(O45="",IF(P42=YEAR(Assumptions!C22)+1,1,""),""))
A46: Loan Proceed | B46: =IF(YEAR(Assumptions!C32)=B42,IF(MONTH(Assumptions!D8)=12,1,IF(MONTH(Assumptions!C32)<MONTH(B40),1,"")),IF(A46="",IF(B42=YEAR(Assumptions!C32)+1,1,""),"")) | C46: =IF(YEAR(Assumptions!C32)=C42,IF(MONTH(Assumptions!D8)=12,1,IF(MONTH(Assumptions!C32)<MONTH(C40),1,"")),IF(B46="",IF(C42=YEAR(Assumptions!C32)+1,1,""),"")) | D46: =IF(YEAR(Assumptions!C32)=D42,IF(MONTH(Assumptions!D8)=12,1,IF(MONTH(Assumptions!C32)<MONTH(D40),1,"")),IF(C46="",IF(D42=YEAR(Assumptions!C32)+1,1,""),"")) | E46: =IF(YEAR(Assumptions!C32)=E42,IF(MONTH(Assumptions!D8)=12,1,IF(MONTH(Assumptions!C32)<MONTH(E40),1,"")),IF(D46="",IF(E42=YEAR(Assumptions!C32)+1,1,""),"")) | F46: =IF(YEAR(Assumptions!C32)=F42,IF(MONTH(Assumptions!D8)=12,1,IF(MONTH(Assumptions!C32)<MONTH(F40),1,"")),IF(E46="",IF(F42=YEAR(Assumptions!C32)+1,1,""),"")) | G46: =IF(YEAR(Assumptions!C32)=G42,IF(MONTH(Assumptions!D8)=12,1,IF(MONTH(Assumptions!C32)<MONTH(G40),1,"")),IF(F46="",IF(G42=YEAR(Assumptions!C32)+1,1,""),"")) -> 1 | H46: =IF(YEAR(Assumptions!C32)=H42,IF(MONTH(Assumptions!D8)=12,1,IF(MONTH(Assumptions!C32)<MONTH(H40),1,"")),IF(G46="",IF(H42=YEAR(Assumptions!C32)+1,1,""),"")) | I46: =IF(YEAR(Assumptions!C32)=I42,IF(MONTH(Assumptions!D8)=12,1,IF(MONTH(Assumptions!C32)<MONTH(I40),1,"")),IF(H46="",IF(I42=YEAR(Assumptions!C32)+1,1,""),"")) | J46: =IF(YEAR(Assumptions!C32)=J42,IF(MONTH(Assumptions!D8)=12,1,IF(MONTH(Assumptions!C32)<MONTH(J40),1,"")),IF(I46="",IF(J42=YEAR(Assumptions!C32)+1,1,""),"")) | K46: =IF(YEAR(Assumptions!C32)=K42,IF(MONTH(Assumptions!D8)=12,1,IF(MONTH(Assumptions!C32)<MONTH(K40),1,"")),IF(J46="",IF(K42=YEAR(Assumptions!C32)+1,1,""),"")) | L46: =IF(YEAR(Assumptions!C32)=L42,IF(MONTH(Assumptions!D8)=12,1,IF(MONTH(Assumptions!C32)<MONTH(L40),1,"")),IF(K46="",IF(L42=YEAR(Assumptions!C32)+1,1,""),"")) | M46: =IF(YEAR(Assumptions!C32)=M42,IF(MONTH(Assumptions!D8)=12,1,IF(MONTH(Assumptions!C32)<MONTH(M40),1,"")),IF(L46="",IF(M42=YEAR(Assumptions!C32)+1,1,""),"")) | N46: =IF(YEAR(Assumptions!C32)=N42,IF(MONTH(Assumptions!D8)=12,1,IF(MONTH(Assumptions!C32)<MONTH(N40),1,"")),IF(M46="",IF(N42=YEAR(Assumptions!C32)+1,1,""),"")) | O46: =IF(YEAR(Assumptions!C32)=O42,IF(MONTH(Assumptions!D8)=12,1,IF(MONTH(Assumptions!C32)<MONTH(O40),1,"")),IF(N46="",IF(O42=YEAR(Assumptions!C32)+1,1,""),"")) | P46: =IF(YEAR(Assumptions!C32)=P42,IF(MONTH(Assumptions!D8)=12,1,IF(MONTH(Assumptions!C32)<MONTH(P40),1,"")),IF(O46="",IF(P42=YEAR(Assumptions!C32)+1,1,""),""))
F49: Assessments for Option 3
B51: =DATE(C54+1,B54,26) -> 45286
B54: =MONTH(Assumptions!D23)-MONTH(Assumptions!D8) -> 0 | C54: =YEAR(Assumptions!D23) -> 2023 | D54: =MONTH(Assumptions!D23) -> 12 | E54: =DAY(Assumptions!D23) -> 30 | G54: =IF(B65="",1,B65) -> 0
B58: =Assumptions!D24*12 -> 120
A60: Loan Clac | B60: =IF((MONTH(B63)-MONTH(Assumptions!D32))+1=12,0,(MONTH(B63)-MONTH(Assumptions!D32))+1) -> 0 | C60: =IF((MONTH(C63)-MONTH(Assumptions!D32))+1=12,0,(MONTH(C63)-MONTH(Assumptions!D32))+1) -> 0 | D60: =IF((MONTH(D63)-MONTH(Assumptions!D32))+1=12,0,(MONTH(D63)-MONTH(Assumptions!D32))+1) -> 0 | E60: =IF((MONTH(E63)-MONTH(Assumptions!D32))+1=12,0,(MONTH(E63)-MONTH(Assumptions!D32))+1) -> 0 | F60: =IF((MONTH(F63)-MONTH(Assumptions!D32))+1=12,0,(MONTH(F63)-MONTH(Assumptions!D32))+1) -> 0 | G60: =IF((MONTH(G63)-MONTH(Assumptions!D32))+1=12,0,(MONTH(G63)-MONTH(Assumptions!D32))+1) -> 0 | H60: =IF((MONTH(H63)-MONTH(Assumptions!D32))+1=12,0,(MONTH(H63)-MONTH(Assumptions!D32))+1) -> 0 | I60: =IF((MONTH(I63)-MONTH(Assumptions!D32))+1=12,0,(MONTH(I63)-MONTH(Assumptions!D32))+1) -> 0 | J60: =IF((MONTH(J63)-MONTH(Assumptions!D32))+1=12,0,(MONTH(J63)-MONTH(Assumptions!D32))+1) -> 0 | K60: =IF((MONTH(K63)-MONTH(Assumptions!D32))+1=12,0,(MONTH(K63)-MONTH(Assumptions!D32))+1) -> 0 | L60: =IF((MONTH(L63)-MONTH(Assumptions!D32))+1=12,0,(MONTH(L63)-MONTH(Assumptions!D32))+1) -> 0 | M60: =IF((MONTH(M63)-MONTH(Assumptions!D32))+1=12,0,(MONTH(M63)-MONTH(Assumptions!D32))+1) -> 0 | N60: =IF((MONTH(N63)-MONTH(Assumptions!D32))+1=12,0,(MONTH(N63)-MONTH(Assumptions!D32))+1) -> 0 | O60: =IF((MONTH(O63)-MONTH(Assumptions!D32))+1=12,0,(MONTH(O63)-MONTH(Assumptions!D32))+1) -> 0 | P60: =IF((MONTH(P63)-MONTH(Assumptions!D32))+1=12,0,(MONTH(P63)-MONTH(Assumptions!D32))+1) -> 0
A61: SA Calc | B61: =IF((MONTH(B63)-MONTH(Assumptions!D22))+1=12,0,(MONTH(B63)-MONTH(Assumptions!D22))+1) -> 0 | C61: =IF((MONTH(C63)-MONTH(Assumptions!D22))+1=12,0,(MONTH(C63)-MONTH(Assumptions!D22))+1) -> 0 | D61: =IF((MONTH(D63)-MONTH(Assumptions!D22))+1=12,0,(MONTH(D63)-MONTH(Assumptions!D22))+1) -> 0 | E61: =IF((MONTH(E63)-MONTH(Assumptions!D22))+1=12,0,(MONTH(E63)-MONTH(Assumptions!D22))+1) -> 0 | F61: =IF((MONTH(F63)-MONTH(Assumptions!D22))+1=12,0,(MONTH(F63)-MONTH(Assumptions!D22))+1) -> 0 | G61: =IF((MONTH(G63)-MONTH(Assumptions!D22))+1=12,0,(MONTH(G63)-MONTH(Assumptions!D22))+1) -> 0 | H61: =IF((MONTH(H63)-MONTH(Assumptions!D22))+1=12,0,(MONTH(H63)-MONTH(Assumptions!D22))+1) -> 0 | I61: =IF((MONTH(I63)-MONTH(Assumptions!D22))+1=12,0,(MONTH(I63)-MONTH(Assumptions!D22))+1) -> 0 | J61: =IF((MONTH(J63)-MONTH(Assumptions!D22))+1=12,0,(MONTH(J63)-MONTH(Assumptions!D22))+1) -> 0 | K61: =IF((MONTH(K63)-MONTH(Assumptions!D22))+1=12,0,(MONTH(K63)-MONTH(Assumptions!D22))+1) -> 0 | L61: =IF((MONTH(L63)-MONTH(Assumptions!D22))+1=12,0,(MONTH(L63)-MONTH(Assumptions!D22))+1) -> 0 | M61: =IF((MONTH(M63)-MONTH(Assumptions!D22))+1=12,0,(MONTH(M63)-MONTH(Assumptions!D22))+1) -> 0 | N61: =IF((MONTH(N63)-MONTH(Assumptions!D22))+1=12,0,(MONTH(N63)-MONTH(Assumptions!D22))+1) -> 0 | O61: =IF((MONTH(O63)-MONTH(Assumptions!D22))+1=12,0,(MONTH(O63)-MONTH(Assumptions!D22))+1) -> 0 | P61: =IF((MONTH(P63)-MONTH(Assumptions!D22))+1=12,0,(MONTH(P63)-MONTH(Assumptions!D22))+1) -> 0
A62: Beg | B62: =DATE(B64,IF(MONTH(Assumptions!D8)=12,1,MONTH(Assumptions!D8)+1),1) -> 41275 | C62: =DATE(C64,IF(MONTH(Assumptions!D8)=12,1,MONTH(Assumptions!D8)+1),1) -> 41640 | D62: =DATE(D64,IF(MONTH(Assumptions!D8)=12,1,MONTH(Assumptions!D8)+1),1) -> 42005 | E62: =DATE(E64,IF(MONTH(Assumptions!D8)=12,1,MONTH(Assumptions!D8)+1),1) -> 42370 | F62: =DATE(F64,IF(MONTH(Assumptions!D8)=12,1,MONTH(Assumptions!D8)+1),1) -> 42736 | G62: =DATE(G64,IF(MONTH(Assumptions!D8)=12,1,MONTH(Assumptions!D8)+1),1) -> 43101 | H62: =DATE(H64,IF(MONTH(Assumptions!D8)=12,1,MONTH(Assumptions!D8)+1),1) -> 43466 | I62: =DATE(I64,IF(MONTH(Assumptions!D8)=12,1,MONTH(Assumptions!D8)+1),1) -> 43831 | J62: =DATE(J64,IF(MONTH(Assumptions!D8)=12,1,MONTH(Assumptions!D8)+1),1) -> 44197 | K62: =DATE(K64,IF(MONTH(Assumptions!D8)=12,1,MONTH(Assumptions!D8)+1),1) -> 44562 | L62: =DATE(L64,IF(MONTH(Assumptions!D8)=12,1,MONTH(Assumptions!D8)+1),1) -> 44927 | M62: =DATE(M64,IF(MONTH(Assumptions!D8)=12,1,MONTH(Assumptions!D8)+1),1) -> 45292 | N62: =DATE(N64,IF(MONTH(Assumptions!D8)=12,1,MONTH(Assumptions!D8)+1),1) -> 45658 | O62: =DATE(O64,IF(MONTH(Assumptions!D8)=12,1,MONTH(Assumptions!D8)+1),1) -> 46023 | P62: =DATE(P64,IF(MONTH(Assumptions!D8)=12,1,MONTH(Assumptions!D8)+1),1) -> 46388
A63: End | B63: =DATE(IF(MONTH(Assumptions!D8)=12,B64,B64+1),MONTH(Assumptions!D8),DAY(Assumptions!D8)) -> 41639 | C63: =DATE(IF(MONTH(Assumptions!D8)=12,C64,C64+1),MONTH(Assumptions!D8),DAY(Assumptions!D8)) -> 42004 | D63: =DATE(IF(MONTH(Assumptions!D8)=12,D64,D64+1),MONTH(Assumptions!D8),DAY(Assumptions!D8)) -> 42369 | E63: =DATE(IF(MONTH(Assumptions!D8)=12,E64,E64+1),MONTH(Assumptions!D8),DAY(Assumptions!D8)) -> 42735 | F63: =DATE(IF(MONTH(Assumptions!D8)=12,F64,F64+1),MONTH(Assumptions!D8),DAY(Assumptions!D8)) -> 43100 | G63: =DATE(IF(MONTH(Assumptions!D8)=12,G64,G64+1),MONTH(Assumptions!D8),DAY(Assumptions!D8)) -> 43465 | H63: =DATE(IF(MONTH(Assumptions!D8)=12,H64,H64+1),MONTH(Assumptions!D8),DAY(Assumptions!D8)) -> 43830 | I63: =DATE(IF(MONTH(Assumptions!D8)=12,I64,I64+1),MONTH(Assumptions!D8),DAY(Assumptions!D8)) -> 44196 | J63: =DATE(IF(MONTH(Assumptions!D8)=12,J64,J64+1),MONTH(Assumptions!D8),DAY(Assumptions!D8)) -> 44561 | K63: =DATE(IF(MONTH(Assumptions!D8)=12,K64,K64+1),MONTH(Assumptions!D8),DAY(Assumptions!D8)) -> 44926 | L63: =DATE(IF(MONTH(Assumptions!D8)=12,L64,L64+1),MONTH(Assumptions!D8),DAY(Assumptions!D8)) -> 45291 | M63: =DATE(IF(MONTH(Assumptions!D8)=12,M64,M64+1),MONTH(Assumptions!D8),DAY(Assumptions!D8)) -> 45657 | N63: =DATE(IF(MONTH(Assumptions!D8)=12,N64,N64+1),MONTH(Assumptions!D8),DAY(Assumptions!D8)) -> 46022 | O63: =DATE(IF(MONTH(Assumptions!D8)=12,O64,O64+1),MONTH(Assumptions!D8),DAY(Assumptions!D8)) -> 46387 | P63: =DATE(IF(MONTH(Assumptions!D8)=12,P64,P64+1),MONTH(Assumptions!D8),DAY(Assumptions!D8)) -> 46752
B64: =Assumptions!$D$7 -> 2013 | C64: =+B64+1 -> 2014 | D64: =+C64+1 -> 2015 | E64: =+D64+1 -> 2016 | F64: =+E64+1 -> 2017 | G64: =+F64+1 -> 2018 | H64: =+G64+1 -> 2019 | I64: =+H64+1 -> 2020 | J64: =+I64+1 -> 2021 | ... P64: =+O64+1 -> 2027
